2018-11-21 15:40:10 ERROR (MainThread) [homeassistant.core] Error doing job: Exception in callback SendfileStreamWriter._sendfile_cb(<Future cancelled>, 11, 10, 27512, 44802, <_UnixSelecto...e debug=False>, True)
Traceback (most recent call last):
  File "/usr/local/lib/python3.5/asyncio/events.py", line 127, in _run
    self._callback(*self._args)
  File "/home/pi/homeassistant/lib/python3.5/site-packages/aiohttp/web_fileresponse.py", line 37, in _sendfile_cb
    loop.remove_writer(out_fd)
  File "/usr/local/lib/python3.5/asyncio/selector_events.py", line 351, in remove_writer
    self._ensure_fd_no_transport(fd)
  File "/usr/local/lib/python3.5/asyncio/selector_events.py", line 258, in _ensure_fd_no_transport
    fd, transport))
RuntimeError: File descriptor 11 is used by transport <_SelectorSocketTransport fd=11 read=polling write=<polling, bufsize=0>>
2018-11-21 15:40:10 ERROR (MainThread) [homeassistant.core] Error doing job: Exception in callback SendfileStreamWriter._sendfile_cb(<Future cancelled>, 11, 10, 27512, 44802, <_UnixSelecto...e debug=False>, True)
Traceback (most recent call last):
  File "/usr/local/lib/python3.5/asyncio/events.py", line 127, in _run
    self._callback(*self._args)
  File "/home/pi/homeassistant/lib/python3.5/site-packages/aiohttp/web_fileresponse.py", line 37, in _sendfile_cb
    loop.remove_writer(out_fd)
  File "/usr/local/lib/python3.5/asyncio/selector_events.py", line 351, in remove_writer
    self._ensure_fd_no_transport(fd)
  File "/usr/local/lib/python3.5/asyncio/selector_events.py", line 258, in _ensure_fd_no_transport
    fd, transport))
RuntimeError: File descriptor 11 is used by transport <_SelectorSocketTransport fd=11 read=polling write=<polling, bufsize=0>>
2018-11-21 15:40:27 ERROR (MainThread) [homeassistant.core] Error executing service <ServiceCall media_player.media_play_pause: entity_id=['media_player.spotify']>
Traceback (most recent call last):
  File "/home/pi/homeassistant/lib/python3.5/site-packages/spotipy/client.py", line 121, in _internal_call
    r.raise_for_status()
  File "/home/pi/homeassistant/lib/python3.5/site-packages/requests/models.py", line 935, in raise_for_status
    raise HTTPError(http_error_msg, response=self)
requests.exceptions.HTTPError: 404 Client Error: Not Found for url: https://api.spotify.com/v1/me/player/play

During handling of the above exception, another exception occurred:

Traceback (most recent call last):
  File "/home/pi/homeassistant/lib/python3.5/site-packages/homeassistant/core.py", line 1002, in _event_to_service_call
    await service_handler.func(service_call)
  File "/home/pi/homeassistant/lib/python3.5/site-packages/homeassistant/components/media_player/__init__.py", line 403, in async_service_handler
    yield from getattr(player, method['method'])(**params)
  File "/usr/local/lib/python3.5/asyncio/futures.py", line 381, in __iter__
    yield self  # This tells Task to wait for completion.
  File "/usr/local/lib/python3.5/asyncio/tasks.py", line 310, in _wakeup
    future.result()
  File "/usr/local/lib/python3.5/asyncio/futures.py", line 294, in result
    raise self._exception
  File "/usr/local/lib/python3.5/concurrent/futures/thread.py", line 55, in run
    result = self.fn(*self.args, **self.kwargs)
  File "/home/pi/homeassistant/lib/python3.5/site-packages/homeassistant/components/media_player/spotify.py", line 232, in media_play
    self._player.start_playback()
  File "/home/pi/homeassistant/lib/python3.5/site-packages/spotipy/client.py", line 913, in start_playback
    return self._put(self._append_device_id("me/player/play", device_id), payload=data)
  File "/home/pi/homeassistant/lib/python3.5/site-packages/spotipy/client.py", line 190, in _put
    return self._internal_call('PUT', url, payload, kwargs)
  File "/home/pi/homeassistant/lib/python3.5/site-packages/spotipy/client.py", line 126, in _internal_call
    headers=r.headers)
spotipy.client.SpotifyException: http status: 404, code:-1 - https://api.spotify.com/v1/me/player/play:
 Player command failed: No active device found
